Workbook

Sheet README
A1: 806 E Ramseur Mini Golf + Bar — P&L model
A3: How to use
A4: 1. Edit inputs on the Assumptions sheet. Blue text = input. Yellow fill = key lever.
A5: 2. The period table (Assumptions!D8:I15) matches the Revenue Estimates web page. 'Copy period table for Excel' on that page pastes into D8.
A6: 3. Set gross margin per revenue line in Assumptions!B19:B23.
A7: 4. Staffing per daypart is on the Labor sheet; hours follow the days and daypart hours on Assumptions.
A8: 5. Black text = formula, green = link from another sheet. Don't type over black cells.
A10: Schedule
A11: Closed Mon-Tue. Weekdays = Wed-Fri, weekends = Sat-Sun. Afternoon 12-5 pm (5 hrs), evening 5-11 pm (6 hrs).
A12: Summer = Apr 1 - Nov 30, winter = Dec 1 - Mar 31. Default day counts use calendar 2027; holidays not removed.
A14: Sheets
A15: P&L — stabilized year split summer / winter / full year, plus a 5-year projection with ramp-up.
... A19: Excludes depreciation, interest/principal split and income taxes. Planning estimates, not quotes.

Sheet P&L
A1: P&L — stabilized year ($)
A2: Summer = Apr-Nov (8 months), winter = Dec-Mar (4 months). Fixed costs, salaries, events and debt split by months; hourly labor by open hours.
A3: Line | B3: Summer | C3: Winter | D3: Full year
A4: Rounds played | B4: =SUM(Assumptions!$J$8:$J$11) -> 31740 | C4: =SUM(Assumptions!$J$12:$J$15) -> 7410 | D4: =B4+C4 -> 39150
A5: Open hours | B5: =SUMPRODUCT(Assumptions!$D$8:$D$11,Assumptions!$E$8:$E$11) -> 1914 | C5: =SUMPRODUCT(Assumptions!$D$12:$D$15,Assumptions!$E$12:$E$15) -> 957 | D5: =B5+C5 -> 2871
A7: Revenue
A8: Golf | B8: =SUM(Assumptions!$J$8:$J$11)*Assumptions!$B$3 -> 380880 | C8: =SUM(Assumptions!$J$12:$J$15)*Assumptions!$B$3 -> 88920 | D8: =B8+C8 -> 469800
A9: Food | B9: =SUMPRODUCT(Assumptions!$J$8:$J$11,Assumptions!$G$8:$G$11) -> 226000 | C9: =SUMPRODUCT(Assumptions!$J$12:$J$15,Assumptions!$G$12:$G$15) -> 53610 | D9: =B9+C9 -> 279610
A10: Ice cream | B10: =SUMPRODUCT(Assumptions!$J$8:$J$11,Assumptions!$H$8:$H$11) -> 73620 | C10: =SUMPRODUCT(Assumptions!$J$12:$J$15,Assumptions!$H$12:$H$15) -> 10245 | D10: =B10+C10 -> 83865
A11: Bar | B11: =SUMPRODUCT(Assumptions!$J$8:$J$11,Assumptions!$I$8:$I$11) -> 326360 | C11: =SUMPRODUCT(Assumptions!$J$12:$J$15,Assumptions!$I$12:$I$15) -> 81705 | D11: =B11+C11 -> 408065
A12: Private events | B12: =Assumptions!$B$4*Assumptions!$B$5*8/12 -> 60000 | C12: =Assumptions!$B$4*Assumptions!$B$5*4/12 -> 30000 | D12: =B12+C12 -> 90000
A13: Total revenue | B13: =SUM(B8:B12) -> 1066860 | C13: =SUM(C8:C12) -> 264480 | D13: =B13+C13 -> 1331340
A15: Gross profit by line
A16: Golf gross profit | B16: =B8*Assumptions!$B$19 -> 361836 | C16: =C8*Assumptions!$B$19 -> 84474 | D16: =B16+C16 -> 446310
A17: Food gross profit | B17: =B9*Assumptions!$B$20 -> 33900 | C17: =C9*Assumptions!$B$20 -> 8041.5 | D17: =B17+C17 -> 41941.5
A18: Ice cream gross profit | B18: =B10*Assumptions!$B$21 -> 51534 | C18: =C10*Assumptions!$B$21 -> 7171.5 | D18: =B18+C18 -> 58705.5
A19: Bar gross profit | B19: =B11*Assumptions!$B$22 -> 248033.6 | C19: =C11*Assumptions!$B$22 -> 62095.8 | D19: =B19+C19 -> 310129.4
A20: Private events gross profit | B20: =B12*Assumptions!$B$23 -> 45000 | C20: =C12*Assumptions!$B$23 -> 22500 | D20: =B20+C20 -> 67500
A21: Total gross profit | B21: =SUM(B16:B20) -> 740303.6 | C21: =SUM(C16:C20) -> 184282.8 | D21: =B21+C21 -> 924586.4
A22: Gross margin | B22: =IF(B13=0,0,B21/B13) -> 0.69390885 | C22: =IF(C13=0,0,C21/C13) -> 0.69677405 | D22: =IF(D13=0,0,D21/D13) -> 0.69447804
A24: Operating costs
A25: Hourly labor (by open hours) | B25: =Labor!$H$14*B5/$D$5 -> 171861.07 | C25: =Labor!$H$14*C5/$D$5 -> 85930.533 | D25: =B25+C25 -> 257791.6
A26: Salaried labor | B26: =Labor!$H$20*8/12 -> 103293.33 | C26: =Labor!$H$20*4/12 -> 51646.667 | D26: =B26+C26 -> 154940
A27: Fixed opex | B27: =Opex!$B$16*8/12 -> 119062.27 | C27: =Opex!$B$16*4/12 -> 59531.133 | D27: =B27+C27 -> 178593.4
A28: Card processing | B28: =(B13-B9)*Assumptions!$B$26 -> 23123.65 | C28: =(C13-C9)*Assumptions!$B$26 -> 5798.925 | D28: =B28+C28 -> 28922.575
A29: Marketing | B29: =B13*Assumptions!$B$27 -> 42674.4 | C29: =C13*Assumptions!$B$27 -> 10579.2 | D29: =B29+C29 -> 53253.6
A30: Total operating costs | B30: =SUM(B25:B29) -> 460014.72 | C30: =SUM(C25:C29) -> 213486.46 | D30: =B30+C30 -> 673501.18
A32: EBITDA | B32: =B21-B30 -> 280288.88 | C32: =C21-C30 -> -29203.658 | D32: =B32+C32 -> 251085.23
A33: EBITDA margin | B33: =IF(B13=0,0,B32/B13) -> 0.26272321 | C33: =IF(C13=0,0,C32/C13) -> -0.11041916 | D33: =IF(D13=0,0,D32/D13) -> 0.18859587
A34: Debt service | B34: =Financing!$B$9*8/12 -> 114712.34 | C34: =Financing!$B$9*4/12 -> 57356.17 | D34: =B34+C34 -> 172068.51
A35: Cash flow after debt | B35: =B32-B34 -> 165576.54 | C35: =C32-C34 -> -86559.829 | D35: =B35+C35 -> 79016.714
A37: Full-year checks
A38: Labor % of revenue | D38: =IF(D13=0,0,Labor!$H$22/D13) -> 0.31001217
A39: Revenue per round | D39: =IF(D4=0,0,D13/D4) -> 34.00613
A40: Debt service coverage (EBITDA / debt service) | D40: =IF(D34=0,0,D32/D34) -> 1.4592166
A41: Cash-on-cash return on equity | D41: =IF(Financing!$B$6=0,0,D35/Financing!$B$6) -> 0.092938972
A44: 5-year projection
A45: Line | B45: Year 1 | C45: Year 2 | D45: Year 3 | E45: Year 4 | F45: Year 5
A46: Volume vs. stabilized | B46: =Assumptions!$B$39 -> 0.75 | C46: =Assumptions!$B$40 -> 0.9 | D46: =Assumptions!$B$41 -> 1 | E46: =Assumptions!$B$42 -> 1.03 | F46: =Assumptions!$B$43 -> 1.06
A47: Revenue | B47: =$D$13*B46 -> 998505 | C47: =$D$13*C46 -> 1198206 | D47: =$D$13*D46 -> 1331340 | E47: =$D$13*E46 -> 1371280.2 | F47: =$D$13*F46 -> 1411220.4
...

Sheet Assumptions
A1: Assumptions
A3: Golf price per round | B3: 12 | C3: One price for all periods
A4: Private events per year | B4: 60 | C4: Birthdays, buyouts
A5: Average event package | B5: 1500 | C5: Revenue split 8/12 summer, 4/12 winter on P&L
A7: Season | B7: Day type | C7: Daypart | D7: Days / yr | E7: Hours / daypart | F7: Players / day | G7: Food $ / player | H7: Ice cream $ / player | I7: Bar $ / player | J7: Rounds / yr | K7: Revenue / yr
A8: Summer | B8: Weekday (Wed-Fri) | C8: Afternoon 12-5 pm | D8: 104 | E8: 5 | F8: 40 | G8: 6 | H8: 4 | I8: 3 | J8: =D8*F8 -> 4160 | K8: =J8*(Assumptions!$B$3+G8+H8+I8) -> 104000
A9: Summer | B9: Weekday (Wed-Fri) | C9: Evening 5-11 pm | D9: 104 | E9: 6 | F9: 70 | G9: 8 | H9: 1 | I9: 16 | J9: =D9*F9 -> 7280 | K9: =J9*(Assumptions!$B$3+G9+H9+I9) -> 269360
A10: Summer | B10: Weekend (Sat-Sun) | C10: Afternoon 12-5 pm | D10: 70 | E10: 5 | F10: 140 | G10: 6 | H10: 4 | I10: 3 | J10: =D10*F10 -> 9800 | K10: =J10*(Assumptions!$B$3+G10+H10+I10) -> 245000
A11: Summer | B11: Weekend (Sat-Sun) | C11: Evening 5-11 pm | D11: 70 | E11: 6 | F11: 150 | G11: 8 | H11: 1 | I11: 16 | J11: =D11*F11 -> 10500 | K11: =J11*(Assumptions!$B$3+G11+H11+I11) -> 388500
A12: Winter | B12: Weekday (Wed-Fri) | C12: Afternoon 12-5 pm | D12: 53 | E12: 5 | F12: 15 | G12: 6 | H12: 2 | I12: 3 | J12: =D12*F12 -> 795 | K12: =J12*(Assumptions!$B$3+G12+H12+I12) -> 18285
A13: Winter | B13: Weekday (Wed-Fri) | C13: Evening 5-11 pm | D13: 53 | E13: 6 | F13: 35 | G13: 8 | H13: 1 | I13: 16 | J13: =D13*F13 -> 1855 | K13: =J13*(Assumptions!$B$3+G13+H13+I13) -> 68635
A14: Winter | B14: Weekend (Sat-Sun) | C14: Afternoon 12-5 pm | D14: 34 | E14: 5 | F14: 60 | G14: 6 | H14: 2 | I14: 3 | J14: =D14*F14 -> 2040 | K14: =J14*(Assumptions!$B$3+G14+H14+I14) -> 46920
A15: Winter | B15: Weekend (Sat-Sun) | C15: Evening 5-11 pm | D15: 34 | E15: 6 | F15: 80 | G15: 8 | H15: 1 | I15: 16 | J15: =D15*F15 -> 2720 | K15: =J15*(Assumptions!$B$3+G15+H15+I15) -> 100640
A16: Total | J16: =SUM(J8:J15) -> 39150 | K16: =SUM(K8:K15) -> 1241340
A17: Day counts: calendar 2027, closed Mon-Tue. Players are per daypart per day.
A18: Revenue line | B18: Gross margin | C18: Note
A19: Golf | B19: 0.95 | C19: Course upkeep sits in fixed costs; Puttshack cites ~95% on mini golf
A20: Food | B20: 0.15 | C20: Food trucks keep their sales; 15% = our commission. Use ~65% if we run food ourselves
A21: Ice cream | B21: 0.7 | C21: ~30% product cost
A22: Bar | B22: 0.76 | C22: ~24% pour cost
A23: Private events | B23: 0.75 | C23: Food + drink in packages
A25: Cost and finance input | B25: Value | C25: Unit / note
A26: Card processing | B26: 0.0275 | C26: % of non-food sales (trucks process their own)
A27: Marketing | B27: 0.04 | C27: % of total sales
A28: Capex contingency | B28: 0.1 | C28: % of non-acquisition capex
A29: Assessed value for property tax | B29: 1800000 | C29: Assumes assessed = purchase price
A30: Durham County tax rate | B30: 0.5792 | C30: $ per $100; FY2026-27 adopted (dconc.gov, June 2026)
A31: City of Durham tax rate | B31: 0.4371 | C31: $ per $100; FY2025-26 proposed (durhamnc.gov); verify adopted
A32: Weeks per year | B32: 52 | C32: For maintenance hours
A33: Hourly payroll burden | B33: 0.1 | C33: FICA + unemployment
A34: Salaried burden incl. benefits | B34: 0.22 | C34: FICA + unemployment + health
A35: Debt as % of total project | B35: 0.7 | C35: SBA 504/7(a) can go higher
A36: Interest rate | B36: 0.0725 | C36: per year
A37: Amortization | B37: 25 | C37: years
... A43: Year 5 volume vs. stabilized | B43: 1.06 | C43: Ramp-up to maturity

Sheet Labor
A1: Labor — tied to the operating schedule on Assumptions
A3: Hourly role | B3: Wkday aft | C3: Wkday eve | D3: Wkend aft | E3: Wkend eve | F3: Hours / yr | G3: Rate | H3: Annual wages | I3: Note
A4: People on shift per daypart (same in summer and winter)
A5: Course host / cashier | B5: 1 | C5: 2 | D5: 2 | E5: 3 | F5: =B5*(Assumptions!$D$8*Assumptions!$E$8+Assumptions!$D$12*Assumptions!$E$12)+C5*(Assumptions!$D$9*Assumptions!$E$9+Assumptions!$D$13*Assumptions!$E$13)+D5*(Assumptions!$D$10*Assumptions!$E$10+Assumptions!$D$14*Assumptions!$E$14)+E5*(Assumptions!$D$11*Assumptions!$E$11+Assumptions!$D$15*Assumptions!$E$15) -> 5581 | G5: 15 | H5: =F5*G5 -> 83715 | I5: Check-in, putters, course flow
A6: Bartender | B6: 1 | C6: 2 | D6: 1 | E6: 3 | F6: =B6*(Assumptions!$D$8*Assumptions!$E$8+Assumptions!$D$12*Assumptions!$E$12)+C6*(Assumptions!$D$9*Assumptions!$E$9+Assumptions!$D$13*Assumptions!$E$13)+D6*(Assumptions!$D$10*Assumptions!$E$10+Assumptions!$D$14*Assumptions!$E$14)+E6*(Assumptions!$D$11*Assumptions!$E$11+Assumptions!$D$15*Assumptions!$E$15) -> 5061 | G6: 7 | H6: =F6*G6 -> 35427 | I6: Base wage above NC tipped minimum ($2.13); tips on top
A7: Ice cream attendant | B7: 1 | C7: 0 | D7: 2 | E7: 1 | F7: =B7*(Assumptions!$D$8*Assumptions!$E$8+Assumptions!$D$12*Assumptions!$E$12)+C7*(Assumptions!$D$9*Assumptions!$E$9+Assumptions!$D$13*Assumptions!$E$13)+D7*(Assumptions!$D$10*Assumptions!$E$10+Assumptions!$D$14*Assumptions!$E$14)+E7*(Assumptions!$D$11*Assumptions!$E$11+Assumptions!$D$15*Assumptions!$E$15) -> 2449 | G7: 14 | H7: =F7*G7 -> 34286 | I7: Afternoon-heavy
A8: Barback / porter | B8: 0 | C8: 1 | D8: 1 | E8: 2 | F8: =B8*(Assumptions!$D$8*Assumptions!$E$8+Assumptions!$D$12*Assumptions!$E$12)+C8*(Assumptions!$D$9*Assumptions!$E$9+Assumptions!$D$13*Assumptions!$E$13)+D8*(Assumptions!$D$10*Assumptions!$E$10+Assumptions!$D$14*Assumptions!$E$14)+E8*(Assumptions!$D$11*Assumptions!$E$11+Assumptions!$D$15*Assumptions!$E$15) -> 2710 | G8: 15 | H8: =F8*G8 -> 40650 | I8: Cleaning, restocking, glassware
A9: Door / security | B9: 0 | C9: 0 | D9: 0 | E9: 1 | F9: =B9*(Assumptions!$D$8*Assumptions!$E$8+Assumptions!$D$12*Assumptions!$E$12)+C9*(Assumptions!$D$9*Assumptions!$E$9+Assumptions!$D$13*Assumptions!$E$13)+D9*(Assumptions!$D$10*Assumptions!$E$10+Assumptions!$D$14*Assumptions!$E$14)+E9*(Assumptions!$D$11*Assumptions!$E$11+Assumptions!$D$15*Assumptions!$E$15) -> 624 | G9: 22 | H9: =F9*G9 -> 13728 | I9: ID checks, closing on weekend nights
A10: Open / close crew | B10: 2 | C10: 1 | F10: =B10*C10*(Assumptions!$D$8+Assumptions!$D$10+Assumptions!$D$12+Assumptions!$D$14) -> 522 | G10: 15 | H10: =F10*G10 -> 7830 | I10: B = staff, C = hours each per open day
A11: Maintenance tech (part-time) | B11: 20 | F11: =B11*Assumptions!$B$32 -> 1040 | G11: 18 | H11: =F11*G11 -> 18720 | I11: B = hours per week, off-hours
A12: Hourly wages | F12: =SUM(F5:F11) -> 17987 | H12: =SUM(H5:H11) -> 234356
A13: Hourly payroll taxes | H13: =Labor!$H$12*Assumptions!$B$33 -> 23435.6
A14: Hourly total, loaded | H14: =Labor!$H$12*(1+Assumptions!$B$33) -> 257791.6
A16: Salaried role | H16: Annual | I16: Note
A17: General Manager | H17: 70000 | I17: Recommended band $65k-$75k + up to 10% bonus
A18: Assistant GM / Bar Manager | H18: 50000 | I18: Durham bar manager postings ~$38k-$67k
A19: GM performance bonus (target) | H19: 7000
A20: Salaried total, loaded | H20: =SUM(H17:H19)*(1+Assumptions!$B$34) -> 154940
A22: Total labor, loaded | H22: =Labor!$H$14+Labor!$H$20 -> 412731.6
A24: Bartender rate is base wage above NC's $2.13 tipped minimum; tips not modeled. Friday counts as a weekday.

Sheet Capex
A1: Initial capex
A2: Enter your amount in column C. Column D keeps the default estimate for reference.
A3: Category | B3: Item | C3: Your amount | D3: Default estimate | E3: Basis
A4: Acquisition | B4: Purchase price | C4: 1800000 | D4: 1800000 | E4: Owner target; broker asking $2.2M ($176/SF)
A5: Acquisition | B5: Closing costs (~2%) | C5: 36000 | D5: 36000 | E5: Legal, title, recording, lender fees
A6: Acquisition | B6: Due diligence: Phase I ESA, survey, inspection, zoning letter | C6: 8000 | D6: 8000 | E6: Owner estimate
A7: Soft costs | B7: Architecture, engineering, permit fees | C7: 25000 | D7: 25000 | E7: Owner estimate
A8: Building | B8: Building upfit: change-of-use code work, sprinklers, egress, restrooms | C8: 200000 | D8: 200000 | E8: Owner estimate; see Issues
A9: Course | B9: 9 covered holes inside building | C9: 100000 | D9: 100000 | E9: Owner estimate
A10: Course | B10: 9 outdoor holes in yard | C10: 100000 | D10: 100000 | E10: Owner estimate
A11: Course | B11: Outdoor site work, drainage, lighting | C11: 75000 | D11: 75000 | E11: Owner estimate
A12: Bar + food | B12: Bar build-out: bar, coolers, draft, ice machine, POS | C12: 175000 | D12: 175000 | E12: Estimate
A13: Bar + food | B13: Ice cream stand: dipping cabinet, freezers, window, sink | C13: 35000 | D13: 35000 | E13: Estimate
A14: Bar + food | B14: Food truck court: power pedestals, pad, grease/trash area | C14: 30000 | D14: 30000 | E14: Estimate
A15: Security | B15: Perimeter security: fence, gates, cameras | C15: 75000 | D15: 75000 | E15: Owner estimate; fence options below
... A19: Opening | B19: Pre-opening: hiring, training, launch marketing, ABC permits | C19: 25000 | D19: 25000 | E19: Owner estimate
B20: Subtotal: acquisition | C20: =SUMIFS(C4:C19,$A$4:$A$19,"Acquisition") -> 1844000 | D20: =SUMIFS(D4:D19,$A$4:$A$19,"Acquisition") -> 1844000
B21: Subtotal: build-out and opening | C21: =SUM(C4:C19)-C20 -> 900000 | D21: =SUM(D4:D19)-D20 -> 900000
B22: Contingency (% on Assumptions) | C22: =C21*Assumptions!$B$28 -> 90000 | D22: =D21*Assumptions!$B$28 -> 90000
B23: Total project cost | C23: =C20+C21+C22 -> 2834000 | D23: =D20+D21+D22 -> 2834000

Sheet Opex
A1: Fixed annual operating costs (year 1)
A3: Item | B3: Year 1 | C3: Basis
A4: Property tax | B4: =Assumptions!$B$29*(Assumptions!$B$30+Assumptions!$B$31)/100 -> 18293.4 | C4: Assessed value assumed = $1.8M; county 57.92c + city 43.71c per $100
A5: Insurance: GL, liquor liability, property, umbrella | B5: 40000 | C5: Estimate; one NC bar operator reports under $20k for a location
A6: Utilities (no HVAC; coolers, fans, lighting, water) | B6: 36000 | C6: Estimate
A7: Building repairs + maintenance | B7: 20000 | C7: Estimate; 1948 Class C building
A8: Course + turf maintenance | B8: 15000 | C8: Estimate
A9: POS, booking, software | B9: 7200 | C9: Estimate
A10: ABC permits + local licenses (renewals) | B10: 3000 | C10: Mixed beverages $1,000; malt $400; wine $400; local
A11: Music licensing (ASCAP/BMI/SESAC) | B11: 3500 | C11: Estimate
A12: Trash, recycling, pest control | B12: 9000 | C12: Estimate
A13: Alarm + camera monitoring | B13: 3600 | C13: Estimate
A14: Accounting + legal | B14: 15000 | C14: Estimate
A15: Operating supplies (balls, putters, scorecards) | B15: 8000 | C15: Estimate
A16: Total fixed opex | B16: =SUM(B4:B15) -> 178593.4

Sheet Financing
A1: Financing
A3: Total project cost | B3: =Capex!$C$23 -> 2834000
A4: Debt % | B4: =Assumptions!$B$35 -> 0.7
A5: Loan amount | B5: =B3*B4 -> 1983800
A6: Equity required | B6: =B3-B5 -> 850200
A7: Interest rate | B7: =Assumptions!$B$36 -> 0.0725
A8: Amortization (years) | B8: =Assumptions!$B$37 -> 25
A9: Annual debt service | B9: =-PMT(B7/12,B8*12,B5)*12 -> 172068.51
